# 📝 01. **'try..catch'와 에러 핸들링**

## 1-1.  try…catch 동작 알고리즘

`try…catch` 문법은 `try`와 `catch`라는 두 개의 주요 블록으로 구성된다.

**✏️ 기본 문법**

```jsx
try {
  // 코드
} catch (err) {
  // 에러 핸들링
}
```

1. `try {…}` 내부의 코드가 실행된다.
2. 에러가 없으면, `try` 내부의 마지막 줄까지 실행되고 `catch` 블록은 건너뛴다.
3. 에러가 발생하는 순간 `try` 블록의 나머지 코드는 실행되지 않고 `catch` 블록으로 즉시 이동한다.

   변수 `error`는 무슨 일이 일어났는지에 대한 설명이 담긴 에러 객체를 포함한다.

<img width="700" alt="Image" src="https://github.com/user-attachments/assets/a7b7897d-d2ef-41f5-b908-d4dde778a5d5" />

## 1-2. 예시 살펴보기

### 1-2-1. 에러가 없는 예시

```jsx
try {
  console.log("try 블록 시작"); // (1)

  // ...에러가 없습니다.

  console.log("try 블록 끝"); // (2)
} catch (err) {
  console.log("에러가 없으므로, catch 블록 실행 안 됨"); // (3)
}
```

### 1-2-2. 에러가 있는 예시

```jsx
try {
  console.log("try 블록 시작"); // (1) 정상 실행

  undefinedVariable; // (2) 에러 발생! catch로 이동

  console.log("try 블록 끝"); // (3) 실행 안 됨 ❌
} catch (err) {
  console.log(`에러 발생: ${err.message}`); // (4) 에러 핸들링됨 ✅
}
```

## 1-3. try…catch 사용 시 주의사항

### ⚠️ `try…catch`는 오직 런타임 에러에만 동작한다.

`try..catch`는 실행 가능한(runnable) 코드 즉, 유효한 자바스크립트 코드에만 동작한다.

```jsx
try {
  console.log("Hello");
  eval("alert('Hi'"); // SyntaxError 발생! (문법 오류)
} catch (e) {
  console.log("이 메시지는 보이지 않습니다."); // 실행되지 않음
}
```

이렇게 유효한 코드에서 발생하는 에러만 처리할 수 있는 것을 “런타임 에러(runtime error)” 혹은 “예외(exception)” 이라고 부른다.

### ⚠️ `try…catch` 는 동기적으로 동작한다.

`setTimeout` 처럼 **‘스케줄 된(scheduled)’ 코드**에서 발생한 예외는 `try..catch`에서 잡아낼 수 없다.

```jsx
try {
  setTimeout(function () {
    undefinedVariable; // try...catch 바깥에서 실행됨
  }, 1000);
} catch (e) {
  console.log("이 메시지는 보이지 않습니다."); // 실행되지 않음
}
```

- `setTimeout` 내의 콜백 함수는 비동기적으로 실행되므로 `try...catch` 범위를 벗어난다.
- `try..catch`를 함수 내부에 위치시켜 해결한다.

⭐️ 스케줄 된 함수 내부의 예외를 잡으려면, 반드시 함수 내부에 `try…catch` 를 구현해야한다.

```jsx
setTimeout(function () {
  try {
    // try .. catch 함수 내부에 구현!!
    undefinedVariable;
  } catch {
    console.log("에러를 잡았습니다!");
  }
}, 1000);
```

## 1-4.  에러 객체와 주요 프로퍼티

에러가 발생하면 자바스크립트는 에러 상세내용이 담긴 객체를 생성한다. 그 다음, `catch` 블록에 이 객체를 인수로 전달한다.

### 내장 에러 전체와 에러 객체가 가지는 주요 프로퍼티

- `name` : 에러 이름. 정의되지 않은 변수 때문에 발생한 에러일 경우 “`ReferenceError`”가 이름이 된다.
- `message` : 에러 상세 내용을 담고 있는 메시지
- `stack` : 현재 호출 스택. 에러를 유발한 중첩 호출들의 순서 정보를 가진 문자열로 디버깅 목적으로 사용된다.

**✅ 사용 예시**

```dart
try {
  lalala; // 에러, 변수가 정의되지 않음
} catch(err) {
  console.log(err.name); // ReferenceError
  console.log(err.message); // lalala is not defined
  console.log(err.stack); // ReferenceError: lalala is not defined at ... (호출 스택)

  // 에러 전체 보기
  console.log(err); // ReferenceError: lalala is not defined
}
```

## 1-5.  선택적 ‘catch’ 바인딩

- 최근에 추가된 문법으로 구식 브라우저는 폴리필이 필요

```dart
try {
  // ...
} catch { // <-- (err) 없이 쓸 수 있음
  // ...
}
```

에러에 대한 자세한 정보가 필요하지 않으면, `catch`에서 이를 생략할 수 있다.

## 1-6. ‘try…catch 실제 사용 예시’

```dart
let json = "{ bad json }";

try {
  let user = JSON.parse(json); // ❌ 에러 발생
  console.log( user.name ); // ❌ 이 코드는 동작하지 않는다.

} catch (e) {
  // 에러가 발생하면 제어 흐름이 catch으로 넘어옴
  console.log( "데이터에 에러가 있어 재요청을 시도합니다." );
  console.log( e.name );
  console.log( e.message );
}
```

## 1-7. throw 연산자 & 직접 에러 만들기

### 1-7-1. throw 연산자

`throw` 연산자는 에러를 생성하며 문법은 아래처럼 작성한다.

```jsx
try {
  throw new Error("테스트 에러");
} catch {
  // (err) 없이 사용 가능 (ES10+)
  console.log("에러를 잡았지만 상세 정보는 사용하지 않음.");
}
```

- 숫자, 문자열 같은 원시형 자료를 포함한 어떤 것이든 에러 객체로 사용할 수 있다.
- 하지만 내장 에러와의 호환을 위해 되도록 에러 객체에 프로퍼티를 넣어주는 것을 권장한다.
- 자바스크립트는 `Error`, `SyntaxError`, `ReferenceError`, `TypeError` 등 표준 에러 객체 관련 생성자를 지원한다. 이를 이용하여 에러 객체를 만들 수 있다.

  ```jsx
  let error = new Error(message);

  let error = new SyntaxError("잘못된 JSON 형식");
  let error = new ReferenceError("존재하지 않는 변수 참조");
  throw new TypeError("잘못된 타입 사용");
  ```

### 1-7-2. 코드 예시로 에러 살펴보기

```jsx
let error = new Error("Error 발생");

console.log(error.name); // Error
console.log(error.message); // Error 발생
```

일반 객체가 아닌 내장 생성자를 사용해 만든 내장 에러 객체의 `name` 프로퍼티는 생성자 이름과 동일한 값을 갖는다. 프로퍼티 `message`의 값은 인수에서 가져온다.

```jsx
try {
  JSON.parse("{ 잘못된 형식의 json }");
} catch (e) {
  console.log(e.name); // SyntaxError
  console.log(e.message); // Unexpected token b in JSON at position 2
}
```

위 코드처럼 잘못된 데이터를 받았을 때, `JSON.parse`는 `SyntaxError` 에러를 만들어낸다.

```jsx
let json = '{ "age": 30 }'; // 불완전한 데이터 (이름이 없는 경우)

try {
  let user = JSON.parse(json); // <-- 에러 없음

  if (!user.name) {
    throw new SyntaxError("불완전한 데이터: 이름 없음"); // 💥
  }

  console.log(user.name);
} catch (e) {
  console.log("JSON Error: " + e.message); // JSON Error: 불완전한 데이터: 이름 없음
}
```

`name` 프로퍼티가 없으면 에러가 발생한 것으로 간주하고 예외 처리를 한 코드이다.

💥 표시한 줄에서 `throw` 연산자는 `message`를 이용해 `SyntaxError`를 생성한다. 에러 생성 방식은 자바스크립트가 자체적으로 에러를 생성하는 방식과 동일하다. (에러 발생 → `try` 실행 중지 → `catch` 문으로 제어 흐름 넘어감)

### 1-7-3. 커스텀 에러 객체 정의하기

```jsx
// 기본 throw 사용
throw new Error("에러 메시지");

// 커스텀 에러 객체 만들기
class CustomError extends Error {
  constructor(message) {
    super(message);
    this.name = "CustomError"; // 에러 이름 설정
  }
}

try {
  throw new CustomError("이건 커스텀 에러입니다.");
} catch (error) {
  console.log(error.name); // CustomError
  console.log(error.message); // 이건 커스텀 에러입니다.
}
```

## 1-8. 에러 다시 던지기 (rethrow)

1. `catch`가 모든 에러를 받는다.
2. `catch(error) {…}` 블록 안에서 에러 객체 `error`를 분석한다.
3. 에러 처리 방법을 알지 못할 경우 `throw error`를 한다.
4. 보통 `instanceof` 명령어로 에러 타입을 체크한다.

✅ **코드 예시 - 에러 다시 던지기로 SyntaxError만 처리되게 하기**

```jsx
try {
  JSON.parse("{잘못된 JSON}");
} catch (error) {
  if (error instanceof SyntaxError) {
    console.log("JSON 에러 처리됨.");
  } else {
    throw error; // 알 수 없는 에러 다시 던지기
  }
}
```

`catch` 블록 안의 💥 표시에서 다시 던져진(rethrow) 에러는 `try…catch` 밖으로 던져진다.

이때 바깥에 `try…catch`가 있다면 여기서 에러를 찾고, 그렇지 않다면 스크립트는 종료된다.

✅ **다시 던져진 예상치 못한 에러 처리하기**

```jsx
function readData() {
  let json = '{ "age": 30 }';

  try {
    // ...
    blabla(); // 에러!
  } catch (err) {
    // ...
    if (!(err instanceof SyntaxError)) {
      throw err; // 알 수 없는 에러 다시 던지기
    }
  }
}

try {
  readData();
} catch (err) {
  console.log("External catch got: " + err); // 에러를 잡음
}
```

위 함수는 `SyntaxError`만 처리할 수 있지만, 함수 바깥의 `try…catch` 에서는 예상하지 못한 에러도 처리할 수 있다.

## 1-9. **try…catch…finally**

`finally`를 추가해서 에러 코드를 하나 더 가질 수 있다.

`finally`는 실행 결과에 상관없이 실행을 완료하고 싶을 때 사용한다.

```jsx
try {
   ... 코드를 실행 ...
} catch(error) {
   ... 에러 핸들링 ...
} finally {
   ... 항상 실행 ...
}
```

- 에러가 없는 경우 : `try` 실행이 끝난 후
- 에러가 있는 경우 : `catch` 실행이 끝난 후

**✅ 사용 예시**

```jsx
try {
  console.log("시작");
  throw new Error("에러 발생!");
} catch (e) {
  console.log("에러 처리");
} finally {
  console.log("무조건 실행됨");
}
```

**작동 흐름**

1. “에러를 만드시겠습니까” ok 일 때 : `try` → `catch` → `finally`
2. No 일 때 : `try` → `finally`

### 1-9-1. 피보나치 함수 예시 코드

```jsx
let num = +prompt("양의 정수를 입력해주세요.", 35);

let diff, result;

function fib(n) {
  if (n < 0 || Math.trunc(n) != n) {
    throw new Error("음수나 정수가 아닌 값은 처리할 수 없습니다.");
  }
  return n <= 1 ? n : fib(n - 1) + fib(n - 2);
}

let start = Date.now();

try {
  result = fib(num);
} catch (e) {
  result = 0;
} finally {
  diff = Date.now() - start;
}

console.log(result || "에러 발생");

console.log(`연산 시간: ${diff}ms`);
```

`fib` 함수가 에러 없이 정상적으로 실행되든 에러가 발생하든 상관없이, `finally`를 사용하면 연산 시간을 제대로 측정할 수 있다.

숫자 `35`를 입력하면 → `try` 다음에 `finally`가 정상적으로 실행되어 연산 시간을 확인할 수 있다.

숫자 `-1` 을 입력하면 → 에러가 발생하면서 연산 시간은 0ms가 된다.

### 1-9-2. try…catch…finally 안의 변수는 지역 변수이다.

`try` 블록 안에서 선언한 변수는 그 블록 안에서만 유효한 지역 변수가 된다.

### 1-9-4. finally와 return

- `finally`절은 `try…catch`절을 빠져나가는 어떤 경우에도 무조건 실행된다.
- `return` 을 사용해서 명시적으로 빠져나가려는 경우도 동일하다.

```jsx
function test() {
  try {
    return "try에서 반환"; // (1) 원래는 이 값이 반환될 예정
  } catch (e) {
    return "catch에서 반환";
  } finally {
    return "finally에서 반환"; // (2) 최종적으로 이 값이 반환됨
  }
}

console.log(test()); // 결과: "finally에서 반환"
```

`finally` 블록에서 `return`이 있으면 `try`의 `return`을 무시하고 `finally`에서 지정한 값이 최종 반환되므로 주의해야한다. (`finally`에서 return이 실행 흐름을 덮어쓸 수 있다)

### 1-9-5. try…finally

`catch` 절이 없는 상황에도 유용하게 쓸 수 있다. `try…finally` 안에서는 에러를 처리하고 싶지 않지만, 시작한 프로세스가 마무리 되었는지 확실히 체크하고 싶을 때 사용한다.

✅ **코드 예시**

```jsx
function func() {
  // 무언가를 측정하는 경우와 같이 끝맺음이 있어야 하는 프로세스
  try {
    // ...
  } finally {
    // 스크립트가 죽더라도 완료됨
  }
}
```

위 코드엔 `catch`가 없기 때문에 `try` 안에서 발생한 에러는 항상 밖으로 떨어져 나온다. `finally`는 실행 흐름이 함수를 떠나기 전에 실행된다.

## 1-10. 전역 catch

자바스크립트 명세서에는 `try…catch`에서 처리하지 못한 에러를 잡을 수 있는 대응 방법이 적혀있지 않다.

브라우저 환경에서는 `window.onerror` 를 이용하여 에러를 처리할 수 있다.

```jsx
window.onerror = function (message, url, line, col, error) {
  console.log(`🔥 에러 발생!`);
  console.log(`메시지: ${message}`);
  console.log(`파일: ${url}`);
  console.log(`위치: ${line}:${col}`);
  console.log(`에러 객체:`, error);
};

/* 출력 예시
메시지: ReferenceError: badFunc is not defined
파일: script.js
위치: 12:5
에러 객체: ReferenceError: badFunc is not defined
*/
```

- `message` : 에러 메시지
- `url` : 에러가 발생한 스크립트의 URL
- `line`, `col` : 에러가 발생한 곳의 줄과 열 번호
- `error` : 에러 객체

### 1-10-1. 실제 사용 예시

```jsx
<script>
  window.onerror = function(message, url, line, col, error) {
    console.log(`에러 발생: ${message} (위치: ${line}:${col})`);
  };

  function readData() {
    badFunc(); // 에러가 발생한 장소
  }

  readData();
</script>
```

⚠️ 전역 핸들러 `window.onerror`는 죽어버린 스크립트를 복구하려는 목적으로 사용하지 않으며, 주로 개발자에게 에러 메시지를 보내는 용도로 사용한다.

**🔗 에러 로깅 관련 상용 서비스 : https://www.muscula.com/docs/get-started/**

1. 서비스를 가입하면 자바스크립트 파일(혹은 스크립트 url)을 받는데, 개발자는 이 파일을 페이지에 삽입한다.
2. 받은 파일은 커스텀 `window.onerror` 함수를 설정
3. 에러가 발생하면, 이 커스텀 함수가 에러에 관한 내용을 담아 서비스에 네트워크 요청 보냄
4. 개발자는 서비스 사이트에 로그인해 기록된 에러를 확인한다.

## 💡 요약

| **개념**         | **설명**                                                |
| ---------------- | ------------------------------------------------------- |
| `try…catch`      | 에러 발생 시 실행 흐름을 변경하여 에러 처리             |
| `catch(error)`   | 에러 객체를 받아 `name`, `message`, `stack` 정보를 제공 |
| `finally`        | 에러 발생 여부와 관계 없이 항상 실행됨                  |
| `throw`          | 강제로 에러를 발생 시킴                                 |
| `rethrow`        | 특정 에러만 처리하고 나머지는 다시 던지기 가능          |
| `window.onerror` | 브라우저 환경에서 전역 에러 핸들링                      |

<br>

---

# 📝 02. 커스텀 에러와 에러 확장

자바스크립트에서는 기본적으로 `Error`, `SyntaxError`, `ReferenceError` 같은 내장 에러 클래스가 제공된다. 하지만 애플리케이션에서 발생하는 특정한 에러 상황을 더 명확하게 표현하기 위해 직접 커스텀 에러 클래스를 만들어 사용할 수 있다.

커스텀 에러는 **기존 Error 클래스를 상속받아** 만들 수 있고, 특정 상황을 처리하는데 필요한 추가적인 속성을 가질 수 있다.

## 2-1. 커스텀 에러 클래스 만들기

### 2-1-1. 기본적인 커스텀 에러 생성

```jsx
class ValidationError extends Error {
  constructor(message) {
    super(message); // 부모 클래스(Error)의 생성자 호출
    this.name = "ValidationError"; // 에러 이름 지정
  }
}

try {
  throw new ValidationError("Invalid data input");
} catch (err) {
  console.log(err.name); // ValidationError
  console.log(err.message); // Invalid data input
  console.log(err.stack); // 에러 발생 위치 포함
}
```

🔍 코드 설명

- `ValidationError`는 `Error` 를 상속받아 만들어졌으며, `message` 를 부모 생성자 (`super`)를 통해 전달한다.
- `name`을 지정하여 어떤 에러인지 명확하게 구별한다.
- `stack` 속성을 통해 에러가 어디에서 발생했는지 확인할 수 있다.

### 2-1-2. 커스텀 에러를 활용한 데이터 검증 (ValidationError)

애플리케이션에서 사용자 입력을 받을 때 데이터 검증이 필요할 수 있다.

사용자 입력이 JSON 형식인지 확인 후, 필요한 필드가 존재하는지 검증하는 함수 (`readUser()`) 함수를 구현한 예시로 확인해보자.

```jsx
class ValidationError extends Error {
  constructor(message) {
    super(message);
    this.name = "ValidationError";
  }
}

// 사용법
function readUser(json) {
  let user = JSON.parse(json); // JSON 파싱

  if (!user.age) {
    throw new ValidationError("No field: age");
  }
  if (!user.name) {
    throw new ValidationError("No field: name");
  }

  return user;
}

// try..catch와 readUser를 함께 사용한 예시
try {
  let user = readUser('{ "age": 25 }'); // name 필드가 없음
} catch (err) {
  if (err instanceof ValidationError) {
    console.log("🚨 Invalid data:", err.message); // Invalid data: No field: name
  } else if (err instanceof SyntaxError) {
    console.log("❌ JSON Syntax Error:", err.message);
  } else {
    throw err; // 알 수 없는 에러는 다시 던지기
  }
}
```

🔍 코드 설명

- JSON 파싱 후 , 필수 필드(`name`, `age`)가 없다면 `ValidationError`를 발생시킨다.
- `try…catch`에서 `instanceof` 를 사용하여 `ValidationError`와 `SyntaxError` 를 구별하여 처리한다.

## 2-2. **더 깊게 상속하기**

### 2-2-1. 커스텀 에러 확장 (상속)

기본 `ValidationError`는 “입력값이 올바른가?” 를 검증하는데 사용되지만, 어떤 필드가 누락되었는지 명확히 하기위해 새로운 클래스 (`PropertyRequiredError`)를 만들어보았다.

**✏️ PropertyRequiredError 클래스 추가**

```jsx
class ValidationError extends Error {
  constructor(message) {
    super(message);
    this.name = "ValidationError";
  }
}

// ✅ ValidationError를 확장한 PropertyRequiredError
class PropertyRequiredError extends ValidationError {
  constructor(property) {
    super(`No property: ${property}`);
    this.name = "PropertyRequiredError";
    this.property = property; // 어떤 필드가 누락되었는지 저장
  }
}

// 사용법
function readUser(json) {
  let user = JSON.parse(json);

  if (!user.age) {
    throw new PropertyRequiredError("age");
  }
  if (!user.name) {
    throw new PropertyRequiredError("name");
  }

  return user;
}

try {
  let user = readUser('{ "age": 25 }'); // name 필드가 없음
} catch (err) {
  if (err instanceof PropertyRequiredError) {
    console.log("❗ Missing property:", err.property); // Missing property: name
  } else if (err instanceof ValidationError) {
    console.log("🚨 Validation Error:", err.message);
  } else if (err instanceof SyntaxError) {
    console.log("❌ JSON Syntax Error:", err.message);
  } else {
    throw err; // 알 수 없는 에러는 다시 던지기
  }
}
```

**🔍 코드 설명**

- `PropertyRequiredError`는 `ValidationError`를 상속받아 필드 누락을 더 구체적으로 처리할 수 있도록 확장했다.
- `property` 속성을 추가하여 어떤 필드가 빠졌는지 확인할 수 있다.

### 2-2-2. 기본 에러 클래스를 만들어 여러 커스텀 에러를 쉽게 관리하기

매번 `this.name = …` 을 설정하는 것이 귀찮을 수 있다. 이를 해결하기 위해 기본적인 커스텀 에러 클래스 (`MyError`)를 추가해보자.

**✏️ MyError 클래스 추가**

```jsx
class MyError extends Error {
  constructor(message) {
    super(message);
    this.name = this.constructor.name; // 자동으로 클래스 이름을 name으로 설정
  }
}

class ValidationError extends MyError {}

class PropertyRequiredError extends ValidationError {
  constructor(property) {
    super(`No property: ${property}`);
    this.property = property;
  }
}

console.log(new PropertyRequiredError("name").name); // PropertyRequiredError
```

**🔍코드 설명**

- `MyError`를 만들고 모든 커스텀 에러가 이를 상속받도록 하면 자동으로 `name`이 설정된다.
- 기존 `this.name = "클래스명"`을 설정하는 번거로움을 줄일 수 있다.

## 2-3. 예외 감싸기 (Wrapping Exception)

에러 종류가 많아지면, 여러 개의 `if(error instatanceof …)`문을 쓰는 것이 비효율적이다.

하나의 “큰 범위 에러(`ReadError`)”로 감싸게 되면, 상세한 원인은 `cause` 속성을 통해 확인 가능하다.

```jsx
class ReadError extends Error {
  constructor(message, cause) {
    super(message);
    this.cause = cause; // ⭐️ 원래 발생한 에러 저장
    this.name = "ReadError";
  }
}

class ValidationError extends Error {}
class PropertyRequiredError extends ValidationError {}

function validateUser(user) {
  if (!user.age) {
    throw new PropertyRequiredError("age");
  }
  if (!user.name) {
    throw new PropertyRequiredError("name");
  }
}

function readUser(json) {
  let user;

  try {
    user = JSON.parse(json);
  } catch (err) {
    throw new ReadError("Syntax Error", err);
  }

  try {
    validateUser(user);
  } catch (err) {
    throw new ReadError("Validation Error", err);
  }
}

try {
  readUser("{ 잘못된 형식의 json }");
} catch (e) {
  if (e instanceof ReadError) {
    console.log("🚨 Read Error:", e.message);
    console.log("🔍 원래 에러:", e.cause);
  } else {
    throw e;
  }
}
```

**🔍코드 설명**

- `ReadError`를 만들어 `SyntaxError`와 `ValidationError`를 감싸도록 구현한다.
- `cause` 속성에 원래 에러를 저장해두면, 필요할 때 원본 에러를 확인할 수 있다.
- `try...catch`에서 `ReadError` 하나만 처리하면 되므로 코드가 간결해진다.

## 💡 요약

| **개념**                | **설명**                                                          |
| ----------------------- | ----------------------------------------------------------------- |
| 커스텀 에러             | `Error`를 상속받아 특정 상황에 맞는 에러 생성                     |
| 커스텀 에러 확장        | `ValidationError` → `PropertyRequiredError` 처럼 계층 구조를 만듦 |
| 기본 커스텀 에러 클래스 | `MyError`를 만들어 name 자동 설정                                 |
| 예외 감싸기             | `ReadError`를 만들어 여러 에러를 하나로 관리                      |

<br>

---

# 📝 03. 에러 설정 추가정리

## 3-1. 다양한 환경에서 에러 처리하는 방법

### 3-1-1. React-Query에서 onError 옵션 사용하기

**⭐️ `onError` 옵션이 필요한 이유는?**

- `useMutation`이나 `useQuery`를 사용할 때 네트워크 요청이 실패할 수 있음
- 이때 `onError` 옵션을 사용하여 실패 시 실행할 코드를 정의한다.

```jsx
import { useMutation } from '@tanstack/react-query';

const addTodo = async (newTodo) => {
  const response = await fetch('/api/todos', {
    method: 'POST',
    body: JSON.stringify(newTodo),
  });

  if (!response.ok) {
    throw new Error('Failed to add todo');
  }

  return response.json();
};

const MyComponent = () => {
  const mutation = useMutation(addTodo, {
    onError: (error, variables, context) => { ✅ onError 적용
      console.error(`🚨 Todo 추가 실패:`, error);
    },
  });

  return (
    <button onClick={() => mutation.mutate({ title: '새로운 할 일' })}>
      할 일 추가
    </button>
  );
};

```

### 3-1-2. react-router-dom에서 에러 설정

**⭐️ RRD에서 오류 설정이 필요한 이유는?**

- 사용자가 존재하지 않는 경로로 접근할 때, 404 페이지로 리디렉션 가능
- API 요청 등의 문제로 인해 특정 페이지를 로드하지 못하면 에러 페이지로 이동
- 라우트 단위에서 에러 핸들링을 하면 개별 페이지에서 불필요한 예외 처리를 줄일 수 있다.

```jsx
import { createBrowserRouter, RouterProvider } from "react-router-dom";
import HomePage from "./HomePage";
import ErrorPage from "./ErrorPage";
import NotFoundPage from "./NotFoundPage";

const router = createBrowserRouter([
  {
    path: "/",
    element: <HomePage />,
    errorElement: <ErrorPage />, // ❌ 해당 페이지 로딩 중 에러 발생 시 ErrorPage로 이동
  },
  {
    path: "*", // ❌ 존재하지 않는 경로로 이동 시 NotFoundPage로 이동
    element: <NotFoundPage />,
  },
]);

export default function App() {
  return <RouterProvider router={router} />;
}
```

- `errorElement` : 페이지를 렌더링하는 중 에러가 발생하면 표시할 에러 페이지를 지정
- `path: '*'` : 사용자가 존재하지 않는 경로에 접근하면 `NotFoundPage`를 보여줌
- 장점: 페이지마다 개별적으로 `try...catch`를 쓰지 않고 라우팅 단에서 한 번에 관리 가능하다.

### 3-1-3. Axios 에서 에러 핸들링

**⭐️ 왜 `axios.interceptors.response` 를 사용할까?**

- API 요청이 실패했을 때 일관된 방식으로 에러를 처리할 수 있음
- 요청이 실패할 경우, 응답 상태에 따라 자동으로 특정 에러 핸들링 로직을 실행 가능
- 모든 `axios` 요청에 대해 공통적인 에러 핸들링이 필요할 때 유용

```jsx
import axios from "axios";

// 🔥 모든 axios 요청에 대한 공통적인 에러 처리 로직 추가
axios.interceptors.response.use(
  (response) => {
    // 성공적인 응답
    return response;
  },
  (error) => {
    // 🚨 요청이 실패했을 때 실행될 로직

    if (error.response) {
      // 서버가 응답을 반환했으나 2xx 범위가 아닌 상태 코드인 경우
      console.error(
        `🚨 서버 오류 (${error.response.status}):`,
        error.response.data
      );
    } else if (error.request) {
      // 요청이 이루어졌으나 응답을 받지 못한 경우 (네트워크 문제)
      console.error(`⚠️ 서버 응답 없음:`, error.request);
    } else {
      // 요청을 보내기 전에 발생한 클라이언트 오류
      console.error(`❌ 요청 설정 오류:`, error.message);
    }

    // 🔥 에러를 다시 throw하여 개별 요청에서 추가 처리 가능하도록 함
    return Promise.reject(error);
  }
);

// ✅ 실제 API 호출 예시
axios
  .get("/api/data")
  .then((response) => console.log("✅ 데이터:", response.data))
  .catch((error) => console.error("❌ 요청 실패:", error));
```

- `axios.interceptors.response.use()`를 사용하여 모든 요청의 에러를 한 곳에서 처리
- `error.response` : 서버에서 응답이 왔지만 2xx 범위가 아닌 경우 (예: 400, 500 오류)
- `error.request` : 요청을 보냈으나 서버가 응답하지 않은 경우 (네트워크 장애)
- `error.message` : 요청 자체가 잘못된 경우 (예: 잘못된 URL)
- 마지막에 `Promise.reject(error)`를 사용하여, 개별 요청에서도 추가적인 핸들링 가능

📚 참고링크 : https://yoonhaemin.com/tag/experience/react-error-handling/

<br>

## 3-2. Sentry 로 에러 로깅하기

Sentry는 프론트엔드 및 백엔드 애플리케이션에서 발생하는 에러를 실시간으로 감지하고 추적하는 에러 모니터링 서비스이다.

React, Vue, Angular, Node.js, Python 등 다양한 플랫폼에서 사용할 수 있다.

에러 발생 시 스택 트레이스, 사용자 정보, 환경 정보 등을 수집하여 분석할 수 있도록 도와준다.

### 3-2-1. Sentry 를 사용하는 이유

1. 에러 추적 자동화 : 코드에서 `try…catch` 를 수동으로 작성하지 않아도 모든 에러를 자동으로 기록한다.
2. 실시간 에러 감지 : 앱에서 발생하는 에러를 실시간으로 알림 받고 대응할 수 있다.
3. 에러 원인 분석 : 발생한 에러의 stack trace 와 관련된 사용자 정보를 제공한다.

### 3-2-2. React에 Sentry 설정하기

Sentry 공식 사이트에서 프로젝트를 생성한 후 DSN을 설정해야한다.

```jsx
// sentryConfig.js

import * as Sentry from "@sentry/react";

Sentry.init({
  dsn: "https://YOUR_DSN_HERE@sentry.io/PROJECT_ID", // Sentry에서 제공하는 DSN 값
  integrations: [new Sentry.BrowserTracing()],
  tracesSampleRate: 1.0, // 0.0 ~ 1.0 사이 값 (1.0이면 모든 트랜잭션 추적)
});
```

### 3-2-3. Sentry로 에러 로깅하기

**✏️ 일반적인 에러 로깅 - Sentry.captureException()**

```jsx
try {
  throw new Error("테스트 에러 발생!");
} catch (error) {
  Sentry.captureException(error);
}
```

이렇게 설정하면 에러를 Sentry 서버로 전송하여 추적 가능

**✏️ React에서 글로벌 에러 핸들링하기**

```jsx
import React from "react";
import * as Sentry from "@sentry/react";

class ErrorBoundary extends React.Component {
  constructor(props) {
    super(props);
    this.state = { hasError: false };
  }

  static getDerivedStateFromError(error) {
    return { hasError: true };
  }

  componentDidCatch(error, errorInfo) {
    Sentry.captureException(error); // ⭐️ Sentry에 에러 로그 전송
  }

  render() {
    if (this.state.hasError) {
      return <h1>⚠️ 예상치 못한 오류가 발생했습니다.</h1>;
    }
    return this.props.children;
  }
}

// 사용 예시
const App = () => (
  <ErrorBoundary>
    <MyComponent />
  </ErrorBoundary>
);

export default App;
```

- 클래스 컴포넌트 기반으로 `componentDidCatch` 를 사용하여 에러를 감지한다.
- `try…catch` 로 감싸기 어려운 컴포넌트 트리 내에서 발생한 렌더링 에러를 감지할 수 있다.
- 특정 UI를 렌더링할 수 있어 사용자가 에러 발생을 인지할 수 있다.

### 3-2-4. React 19에서 제공하는 새로운 에러 핸들링 방식

**✏️ 기존 방식의 한계점**

- 클래스 컴포넌트 기반이기에 함수형 컴포넌트에서 사용하기 어렵다.
- 컴포넌트 렌더링 중 발생한 에러만 감지할 수 있다.
- ErrorBoundary를 감싸지 않은 컴포넌트에서는 에러를 잡을 수 없다.
- React 내부에서 복구할 수 있는 에러는 감지할 수 없다.

**✏️ 개선된 에러 핸들링 특징**

- React19 의 createRoot에서 제공하는 에러 핸들러 옵션 (`onUncaughtError`, `onCaughtError`, `onRecoverableError`)을 사용함
- ErrorBoundary가 없어도 애플리케이션 전역에서 발생한 에러를 감지 가능
- React 내부에서 자동 복구한 에러까지 추적 가능

✅ 코드 예시

```jsx
import React from "react";
import { createRoot } from "react-dom/client";
import * as Sentry from "@sentry/react";

const container = document.getElementById("app");

const root = createRoot(container, {
  // ErrorBoundary에 의해 잡히지 않은 치명적인(Uncaught) 에러 처리
  onUncaughtError: Sentry.reactErrorHandler((error, errorInfo) => {
    console.warn("Uncaught error", error, errorInfo.componentStack);
  }),
  // React 내부에서 ErrorBoundary로 잡힌 에러 처리
  onCaughtError: Sentry.reactErrorHandler(),
  // React가 자동으로 복구한 에러 처리
  onRecoverableError: Sentry.reactErrorHandler(),
});

root.render(<App />);
```

**📚 참고링크** : https://docs.sentry.io/platforms/javascript/guides/react/
