# try..catch와 에러 핸들링
프로그래밍에 능한 사람이더라도
실수, 예상치못한 사용자 입력, 잘못된 서버 응답 등의 수천만 가지의 이유때문에
에러가 있는 스크립트를 작성할 수 있다.

에러가 발생하면 스크립트는 죽고(즉시 중단되고) 콘솔에 에러가 출력된다.

그러나 try..catch 문법을 사용하면 스크립트가 죽는 걸 방지하고, 에러를 잡아서 더 합당한 무언가를 할 수 있게 된다.

## try..catch 문법
try..catch 문법은 try와 catch 라는 두 개의 주요 블록을 구성된다.

## 동작 알고리즘
1. 먼저, try {...}  안의 코드가 실행된다.
2. 에러가 없다면 try안의 마지막 줄까지 실행되고 catch블록은 건너뛴다.
3. 에러가 있다면 try안 코드의 실행이 중단되고, catch(error)블록으로 제어 흐름이 넘어간다.
   변수 err는 무슨 일이 일어낫는지에 대한 설명이 담긴 에러 객체를 포함한다.

이렇게 try 블록 안에서 에러가 발생해도 catch에서 에러를 처리하기 때문에 스크립트는 죽지 않는다.

## try..catch는 오직 런타임 에러에만 동작
try..catch는 실행가능한 코드에만 동작한다.
실행 가능한 코드는 유효한 자바스크립트 코드를 의미한다.

중괄호 짝이 안 맞는 것처럼 문법적으로 잘못된 경우엔 try..catch가 동작하지 않는다.

자바스크립트 엔진은 코드를 읽고 난 후 코드를 실행한다.
코드를 읽는 중에 발생하는 에러는 parse-time 에러 라고 부르는데, 엔진은 이 코드를 이해할 수 없기 때문에 parse-time에러는 코드 안에서 복ㄱ구가 불가능히다.

try..catch는 유효한 코드에서 발생하는 에러만 처리할 수 있다.
이런 에러를 런타임 에러 혹은 예외라고 부른다.

## try..catch는 동기적으로 동작한다.
setTimeout처럼 스케줄 된 코드에서 발생한 예외는 try..catch에서 잡아낼 수 없다.

```jsx
try {
  setTimeout(function() {
    noSuchVariable; // 스크립트는 여기서 죽는다.
  },1000);
} catch (e) {
  alert("작동 멈춤");
}
```

setTimeout에 넘겨진 익명함수는 엔진이 try..catch를 떠난 다음에서야 실행되기 때문이다.
스케줄된 함수 내부의 예외를 잡으려면 try..catch를 반드시 함수 내부에 구현해야한다.

```jsx
setTimeout(function(){
  try {
    noSuchVariable; // 이제 try...catch에서 에러를 핸들링 가능
  } catch {
    alert("에러를 잡았습니다!")
  }
},1000)
```

## 에러 객체
에러가 발생하면 자바스크립트는 에러 상세내용이 담긴 객체를 생성한다.
그 후, catch블록에 이 객체를 인수로 전달한다.
(err 대신 다른 이름으로도 쓸 수 있음)

내장 에러 전체와 에러 객체는 두 가지 주요 프러퍼티를 가진다.

name: 에러 이름. 정의 되지 않은 변수 때문에 발생한 에러라면 ReferenceError가 이름이 된다.
message: 에러 상세 내용을 담고 있는 문자 메시지

표준은 아니지만 name과 message이외에 대부분의 호스트 환경에서 지원하는 프로퍼티도 있다.
stack은 가장 널리 사용되는 비표준 프로퍼티 중 하나이다.

stack 
현재 호츨 스택. 에러를 유발한 중첩 호출들의 순서 정보를 가진 문자열로 디버깅 목적으로 사용된다.

예시: 
```jsx
try {
  lalala; // 에러 변수가 정의되지 않음
} catch(erro){
  alert(err.name); // ReferenceError
  alert(err.message); // lalala is not defined
  alert(err.stack); // ReferenceError: lalala is not defined at ... (호출 스택) 

  // 에러 전체를 보여줄 수도 있다.
  // 이때, 에러 객체는 "name: message" 형태의 문자열로 변환된다.
  alert(err); // ReferenceError: lalala is not defined
}
```

## 선택적 'catch'바인딩
에러에 대한 자세한 정보가 필요하지 않으면 catch에서 생략할 수 있다. 
하지만, 스펙에 추가된 지 얼마 안 된 문법이고, 구식 브라우저는 폴리필이 필요하다.
```jsx
try {
  // ...
} catch { // <-- (err) 없이 쓸 수 있음
  // ...
}
```

## try..catch사용하기
예시
```jsx
let json = '{"name":"John", "age": 30}'; // 서버로부터 전달받은 데이터

let user = JSON.parse(json); // 전달받은 문자열을 자바스크립트 객체로 변환

// 문자열 형태로 전달받은 user가 프로퍼티를 가진 객체가 됨
alert( user.name ); // John
alert( user.age );  // 30
```
#### 잘못된 형식의 json이 들어온 경우, JSON.parse는 에러를 만들기 때문에 스크립트가 죽는다.

서버에서 전달받은 데이터가 잘못되어 스크립트가 죽는 경우, 
사용자는 개발자 콘솔을 열지 않는 이상 절대 원인을 알 수 없다.

try..catch를 사용해 이를 처리해보자.
```jsx
let json = "{ bad json }";
try {
  let user - JSON.parse(json); // 여기에서 에러가 발생
  alert(user.name) // 동작하지 않는다.
} catch(e) {
  // 에러가 발생하여 제어의 흐름이 catch문으로 넘어왔다.
  alert( "데이터에 에러가 있어 재요청을 시도합니다." );
  alert( e.name );
  alert( e.message );
}
```

위 예시에선 에러가 발생했다는 걸 보여주기 위해 간단히 예외처리했지만, catch블록 안에서 새로운 네트워크 요청 보내기,
사용자에게 대안 제안하기, 로깅 장치에 에러 정보 보내기 등과 같은 구체적인 일을 할 수 있다.

## 직접 에러를 만들어서 던지기
json이 문법적으로 잘못되진 않았지만, 스크립트 내에서 사용 중인 필수 프로퍼티 name을 가지고 있지 않다면 무슨 일이 생길까?

let json =  `{"age": 30}`; // 불완전한 데이터
try {
  let user = JSON.parse(json); // 에러 없음
  alert(user.name); //undefined
} catch (e) {
  alert("실행되지 않습니다.")
}
위 예시에서 JSON.parse는 정상적으로 실행되었지만 name이 없는 건 에러를 유발하는 상황이다.
이제 trhow연산자를 사용헤 에러 처리를 통합해보겠다.

## trhow 연산자
문법: 
`throw <error object>`

이론적으로는 숫자, 문자열 같은 원시형 자료를 포함한 어떤 것이든
에러 객체로 사용할 수 있다. 
하지만 내장 에러와의 호환을 위해 되도록 에러 객체에 name과 message 프로퍼티를 넣어주는 것을 권장한다.

자바스크립트는 아래와 같이 Error, SyntaxError, ReferenceError, TypeError등의 표준 에러 객체 관련 생성자를 지원한다.

```jsx
let error = new Error(message);
// or
let error = new SyntaxError(message);
let error = new ReferenceError(message);
// ...
```

일반 객체가 아닌 내장 생성자를 사용해 만든 내장 에러 객체의 name프로퍼티는 생성자 이름과 동일한 값을 갖는다.
프로퍼티 mesage의 값은 인수에서 가져온다. 

예시
```jsx
let error = new Error("이상한 일이 발생했습니다. o_O");

alert(error.name); // Error
alert(error.message); // 이상한 일이 발생했습니다. o_O
```

잘못된 데이터를 받았을 때, JSON.parse가 어떤 종류의 에러를 만들어내는지 아래 코드를 통해 살펴보자.

```jsx
try {
  JSON.parse("{ 잘못된 형식의 json o_O }");
} catch(e) {
  alert(e.name); // SyntaxError
  alert(e.message); // Unexpected token b in JSON at position 2
}
```
SyntaxError 발생 
사용자를 나타내는 객체에 name프로퍼티는 반드시 있어야하므로, 이제 name이 없으면 에러가 발생한 것으로 간주하고 예외 처리를 해보자.
trhow 연산자를 사용해 에러를 던져보자.

```jsx
let json = '{ "age": 30 }'; // 불완전한 데이터
try {

  let user = JSON.parse(json); // <-- 에러 없음

  if (!user.name) {
    throw new SyntaxError("불완전한 데이터: 이름 없음"); // (*)
  }

  alert( user.name );

} catch(e) {
  alert( "JSON Error: " + e.message ); // JSON Error: 불완전한 데이터: 이름 없음
}
```

(*)로 표시한 줄에서 throw 연산자는 message를 이용해 SyntaxError을 생성한다.
에러 생성 방식은 자바스크립트가 자체적으로 에러를 생성하는 방식과 동일하다.
에러가 발생했으므로, try실행은 즉시 중단되고, 제어 흐름이 catch로 넘어간 것을 얼럿 창을 통해 확인할 수 있다.

이제 JSON.parse에서 에러가 발생한 경우를 포함해서 모든 에러를 catch블록 안에서 처리할 수 있게 되었다.

## 에러 다시 던지기
위 예시에선 불완전한 데이터를 try..catch로 처리해였다. 그런데 또 다른 예기치 에러가 try블록 안에서 발생할 수도 있다.
정의되지 않은 변수 사용 등의 프로그래밍 에러가 발생할 가능성은 항상 있다.

```jsx
let json = '{ "age": 30 }'; // 불완전한 데이터

try {
  user = JSON.parse(json); // <-- user 앞에 let을 붙이는 걸 잊었네요.

  // ...
} catch(err) {
  alert("JSON Error: " + err); // JSON Error: ReferenceError: user is not defined
  // (실제론 JSON Error가 아닙니다.)
}
```

위 예시에서는 에러 종류와 관계없이 JSON Error메서지를 보여준다.
이렇게 에러 종류와 관계없이 동일한 방식으로 에러를 처리하는 것은 디버깅을 어렵게 만들기 때문에 좋지 않다.
이런 문제를 피하고자 다시 던지기(rethrowing)기술을 사용한다.

#### catch는 알고 있는 에러만 처리하고 나머지는 다시 던저야한다.
1. catch가 모든 에러를 받는다.
2. catch(error) {...} 블록 안에서 에러 객체를 err 분석한다.
3. 에러 처리 방법을 알지 못하면 throw err를 한다.

보통 에러 타입을 instanceof명령어로 체크한다.
```jsx
try {
  user = { /*...*/ };
} catch(err) {
  if (err instanceof ReferenceError) {
    alert('ReferenceError'); //  정의되지 않은 변수에 접근하여 'ReferenceError' 발생
  }
}
```

error.name 프로퍼티로 에러 클래스 이름을 알 수도 있다.
기본형 에러는 모두 err.name 프로퍼티를 가진다.
또는 err.constructor.name을 사용할 수도 있다.

에러를 다시 던져서 catch 블록에선 SyntaxError만 처리되보도록 해보자.

```jsx
let json = '{ "age": 30 }'; // 불완전한 데이터
try {
  let user = JSON.parse(json);

  if(!user.name) {
    throw new SyntaxError("불완전한 데이터: 이름 없음")
  }
  blabla(); // 예상치 못한 에러
  alert(user.name);
} catch (e) {
  if(e instanceof SyntaxError) {
    alert("JSON Error: " + e.message);
  } else {
    throw e; // 에러 다시 던지기
  }
}
```

catch 블록 안의 (*)로 표시한 줄에서 다시 던져진 trethrow에러는 try ...catch 밖으로 던져진다.
이때 바깥에 try..catch가 있다면 여기서 에러를 잡는다. 
아니라면 스크립트는 죽을 것이다.

이렇게 하면 catch블록에선 어떻게 다룰지 알고 있는 에러만 처리하고, 알 수 없는 에러는 건너뛸 수 있다.

이제 try..catch를 하나 더 만들어, 다시 던져진 예상치 못한 처리를 해보자.

```jsx
function readData(){
  let json = `{"age":30}`;

  try {
    //...
    blabla(); // 에러!
  } catch (e) {
    //...
    if(!(e instanceof SysntaxError)){
      trhow e; // 알 수 없는 에러 다시 던지기
  }
}

try {
  readData();
} catch(e) {
  alert("External catch got: " + e); // 에러를 잡음
}
```

readData는 SyntaxError만 처리할 수 있지만, 함수 바깥의 try...catch에서는 예상치 못한 에러도 처리할 수 있게 되었다.

## try..catch...finally
try..catch는 fainally라는 절을 하나 더 가질 수 있다.

finally {
  .. 항상 실행...
}

finally절은 무언가를 실행하고 실행 결과에 상관 없이 실행을 완료하고 싶을 경우 사용된다. 
try블록 안에 return 이 있더라도, 바깥 코드로 반환되기 전에 finally가 실행된다.

### 전역 catch
호스트 환경을 확인하세요 
이 절은 코어 자바스크립트가 아닙니다.

즉, 전역 catch는 호스트환경(예: 브라우저나 Node.js)에서 제공하는 기능이지, 자바스크립트 언어 자체의 기능이 아니라는 의미이다.

try..catch바깥에서 치명적인 에러가 발생해 스크립트가 죽었다고 가정했을 때, 
대처방법에는 어딘가에 에러 내역을 기록해 놓거나, 사용자에게 에러가 발생했음을 알려주는 행위를 할 수 있다.

자바스크립트 명세서에는 이런 치명적인 에러에 대응하는 방법이 적혀있지 않다.
하지만 try..catch에서 처리하지 못한 에러를 잡는 것은 아주 중요하기 때문에
자바스크립트 호스트 환경 대다수는 자체적으로 에러 처리 기능을 제공한다.

Node.js의 proces.on("uncaughtException")이 그 예이다.
브라우저 환경에선 window.onerror을 이용해 에러를 처리할 수 있다.
window.onerror 프로퍼티에 함수를 할당하면 예상치 못한 에러가 발생했을 때 이 함수가 실행된다.

```jsx
window.onerror =  function (message, url, line, col, error {
  // ...
}
```

- message: 에러메시지
- url: 에러가 발생한 스크립트의 URL
- line, col : 에러사 발생한 곳의 줄과 열 번호
- error: 에러 객체

예시
```jsx
<script>
  window.onerror = function(message, url, line, col, error) {
    alert(`${message}\n At ${line}:${col} of ${url}`);
  };

  function readData() {
    badFunc(); // 에러가 발생한 장소
  }

  readData();
</script>
```

그런데 전역 핸들러 window.onerror는 죽어버린 스크립트를 복구하려는 목적으로는 잘 사용하지 않는다.
프로그래밍 에러가 발생한 경우 window.onerror만으로 스크립트를 복구하는것은 사실상 불가능하다.

window.onerror는 개발자에게 에러 메시지를 보내는 용도로 사용한다.
이 외에 https://errorception.com 나 http://www.muscula.com같은 에러 로깅 관련 상용 서비스가 여러 가지 있다.

이런 서비스들은 다음과 같은 프로세스로 동작한다.

1. 서비스를 가입하면 자바스크립트 파일(혹은 스크립트 url)을 받는데, 개발자는 이 파일을 페이다.

throw연산자를 사용하면 에러를 직접 만들 수 있다.
이론상으론, throw인수에 모든 것을 넘길 수 있지만, 대개 내장 Error클래스를 상속받은 에러 객체를 인수에 넘긴다.

다시 던지기는 에러 처리 시 사용되는 중요한 패턴이다.
catch블록에선 대개 예상하였거나 어떻게 다룰지 알고 있는 에러를 다루고, 예상치 못한 에러는 다시 던지기 한다.

try...catch가 없어도 대부분의 호스트 환경이 전역 에러 핸들러를 지원하기 때문에 떨어져나온 에러를 잡을 수 있다.
window.onerror는 브라우저 환경의 전역 에러 핸들러이다.

## 에러핸들링

### 커스텀 에러와 에러 확장

개발을 하다 보면 자체 에러 클래스가 필요한 경우가 종종 생긴다.  
예를 들어, 네트워크 관련 작업 중 에러가 발생했다면 `HttpError`, 데이터베이스 관련 작업 중 에러가 발생했다면 `DbError`, 검색 관련 작업 중 에러가 발생했다면 `NotFoundError`를 사용하는 것이 직관적이다.  

이때, 에러 클래스는 `message`나 `name`이 가능하다면 `stack` 프로퍼티도 지원해야 한다. 물론 이런 프로퍼티 이외에도 다른 프로퍼티를 지원할 수 있다.  

`HttpError` 클래스의 객체에 `statusCode` 프로퍼티를 만들고 `404`, `403`, `500` 같은 숫자를 값으로 지정할 수 있다.  

앞서 배운 바와 같이 `throw`의 인수엔 아무런 제약이 없기 때문에 커스텀 에러 클래스는 반드시 `Error`를 상속할 필요가 없다.  

그렇지만 `Error`를 상속받아 커스텀 에러 클래스를 만들게 되면 `obj instanceof Error`를 사용해서 에러 객체를 식별할 수 있다는 장점이 생긴다.  

이런 장점 때문에 맨땅에서 커스텀 에러 객체를 만드는 것보다 `Error`를 상속받아 커스텀 에러 객체를 만드는 것이 낫다.  

애플리케이션 크기가 점점 커지면 우리가 만들게 될 커스텀 에러 클래스들은 자연스레 계층 구조를 형성하게 된다.  
예를 들어 `HttpTimeoutError`는 `HttpError`를 상속받는 식으로 말이다.  

### 에러 확장하기

사용자 데이터가 저장된 JSON을 읽는 함수 `readUser(json)`이 있다고 가정해보자.  
유효한 JSON은 다음과 같은 형태여야 한다.  

```js
let json = `{ "name": "John", "age": 30 }`;
```

`readUser` 내부에선 `JSON.parse`를 이용하게 된다.  
따라서 잘못된 형식의 JSON이 들어오면 `SyntaxError`가 발생한다.  
그런데 인수로 받은 데이터가 JSON 형식이긴 하지만, 유효한 사용자일 것이라는 보장은 없다.  
사용자 데이터라면 필수적으로 있어야 할 `name`이나 `age`가 누락되었을 수 있다.

따라서 `readUser(json)`은 JSON 형식의 데이터를 읽을 수 있을 뿐만 아니라, 데이터를 검증할 수 있어야 한다.  
필수 프로퍼티가 없거나 위 형식에 맞지 않으면 에러를 발생시킬 수 있어야 한다.  
그런데 이때 발생하는 에러는 `SyntaxError`가 아니다.  
JSON 형식은 맞지만, 자체 기준에 맞지 않기 때문에 발생한 에러이므로 전혀 다른 종류의 에러다.  

지금부터 이 에러를 `ValidationError`라고 부르겠다.  
자, 이제 `ValidationError`를 위한 클래스를 만들어보자.

### ValidationError에서 Error를 상속받기

```js
class ValidationError extends Error {
  constructor(message) {
    super(message); // (1)
    this.name = "ValidationError"; // (2)
  }
}

function test() {
  throw new ValidationError("에러 발생!");
}

try {
  test();
} catch (err) {
  alert(err.message); // 에러 발생
  alert(err.name); // ValidationError
  alert(err.stack); // 각 행 번호가 있는 중첩된 호출들의 목록
}
```

(1)에서 부모 생성자를 호출하고 있다.  
자바스크립트에서는 자식 생성자 안에서 `super`를 반드시 호출해야 한다.  
`message` 프로퍼티는 부모 생성자에서 설정된다.  

부모 생성자에선 `message`뿐만 아니라 `name` 프로퍼티도 설정(`Error`)하기 때문에 (2)에서 원하는 값으로 재설정해줘야 한다.

### `readUser(json)` 안에서 ValidationError 사용하기

```js
class ValidationError extends Error {
  constructor(message) {
    super(message);
    this.name = "ValidationError";
  }
}

// 사용법
function readUser(json) {
  let user = JSON.parse(json);

  if (!user.age) {
    throw new ValidationError("No field: age");
  }
  if (!user.name) {
    throw new ValidationError("No field: name");
  }
  return user;
}

// try...catch와 readUser를 함께 사용한 예시
try {
  let user = readUser('{ "age": 25 }');
} catch (err) {
  if (err instanceof ValidationError) {
    alert("Invalid data: " + err.message); // Invalid data: No field: name
  } else if (err instanceof SyntaxError) { // (*)
    alert("JSON Syntax Error: " + err.message);
  } else {
    throw err; // 알려지지 않은 에러는 재던지기 (**)
  }
}
```

이 과정에서 `instanceof`로 에러 유형을 확인했다.  
에러 유형 확인은 `instanceof` 말고 `err.name`을 사용해도 가능하다.

```js
else if (err.name == "SyntaxError"){}
```

그런데 에러 유형 확인은 `err.name`보다는 `instanceof`를 사용하는 게 훨씬 좋다.  
나중에 `ValidationError`를 확장하여 `PropertyRequiredError` 같은 새로운 확장 에러를 만들게 될 텐데, `instanceof`는 새로운 상속 클래스에서도 동작하기 때문이다.  

`catch`에 알려지지 않은 에러가 있을 때 이 에러는 재던지기 된다는 점을 유의해야 한다.  
`catch` 블록에선 유효성 검사와 문법 오류만 처리하고 다른 종류의 에러는 밖으로 던져야 한다.

### 더 깊게 상속하기

앞서 만든 `ValidationError` 클래스는 너무 포괄적이어서 뭔가 잘못될 확률이 있다.  
꼭 필요한 프로퍼티가 누락된거나, `age`에 문자열 값이 들어가는 것처럼 형식이 잘못된 경우를 처리할 수 없다.  
필수 프로퍼티가 없는 경우에 대응할 수 있도록 좀 더 구체적인 클래스 `PropertyRequiredError`를 만들어보자.  
`PropertyRequiredError`엔 누락된 프로퍼티에 대한 추가 정보가 담겨야 한다.

```js
class ValidationError extends Error {
  constructor(message) {
    super(message);
    this.name = "ValidationError";
  }
}

class PropertyRequiredError extends ValidationError {
  constructor(property) {
    super("No property: " + property);
    this.name = "PropertyRequiredError";
    this.property = property;
  }
}

// 사용법
function readUser(json) {
  let user = JSON.parse(json);

  if (!user.age) {
    throw new PropertyRequiredError("age");
  }
  if (!user.name) {
    throw new PropertyRequiredError("name");
  }
  return user;
}

try {
  let user = readUser('{ "age": 25 }');
} catch (err) {
  if (err instanceof ValidationError) {
    alert("Invalid data: " + err.message); // Invalid data: No property: name
    alert(err.name); // PropertyRequiredError
    alert(err.property); // name
  } else if (err instanceof SyntaxError) {
    alert("JSON Syntax Error: " + err.message);
  } else {
    throw err; // 알려지지 않은 에러는 재던지기
  }
}
```

새롭게 만든 클래스 `PropertyRequiredError`는 사용하기 쉽다.  
`new PropertyRequiredError(property)`처럼 프로퍼티 이름을 전달하기만 하면 된다.  
사람이 읽을 수 있는 `message`는 생성자가 알아서 만들어준다.

여기서 주목할 점은 `PropertyRequiredError` 생성자 안에서 `this.name`을 수동으로 할당해주었다는 것이다.  
그런데 이렇게 매번 커스텀 에러 클래스의 생성자 안에서 `this.name`을 수동으로 할당해주는 것은 귀찮은 작업이다.  

이런 번거로운 작업은 기본 에러 클래스를 만들고 커스텀 에러들이 이 클래스를 상속받게 하면 피할 수 있다.  

기본 에러 생성자에 `this.name = this.constructor.name`을 추가하면 된다.  

기본 에러 클래스를 `MyError`라고 설정하면, `MyError`를 사용해 커스텀 에러 클래스를 간결하게 만들 수 있다.

```js
class MyError extends Error {
  constructor(message) {
    super(message);
    this.name = this.constructor.name;
  }
}

class ValidationError extends MyError { }

class PropertyRequiredError extends ValidationError {
  constructor(property) {
    super("No property: " + property);
    this.property = property;
  }
}

// 제대로 된 이름이 출력됩니다.
alert( new PropertyRequiredError("field").name ); // PropertyRequiredError
```

`this.name = ...`이 사라졌기 때문에 `ValidationError` 같은 커스텀 에러의 생성자가 더 깔끔해진 것을 확인할 수 있다.

### 예외 감싸기

함수 `readUser`는 사용자 데이터를 읽기 위한 용도로 만들어졌다.  
그런데 사용자 데이터를 읽는 과정에서 다른 오류가 발생할 수 있다.  
지금 당장은 `SyntaxError`와 `ValidationError`를 사용해 에러를 처리하고 있는데, 앞으로 `readUser`가 더 커지면 다른 커스텀 에러 클래스를 만들어야 할 것이다.

`readUser`를 호출하는 곳에선 새롭게 만들어질 커스텀 에러들을 처리할 수 있어야 한다.  
그런데 지금은 `catch` 블록 안에 `if`문 여러 개를 넣어 종류를 알 수 있는 에러를 처리하고, 그렇지 않은 에러는 다시 던지기 해 처리하고 있다.  

`readUser`의 기능이 커지면서 에러 종류가 많아질 텐데, 그때마다 에러 종류에 따라 에러 처리 분기문을 매번 추가해야 하나? 라는 의문이 생길 수 있다.  

하지만 보통은 그렇지 않다.  
실제 우리가 필요로 하는 정보는 데이터를 읽을 때 에러가 발생했는지 여부이다.  
필요할 때 에러 세부사항에 대한 정보를 얻을 수 있는 방법이 있다면 더 좋지만, 왜 에러가 발생했는지와 자세한 설명은 대부분의 경우 필요하지 않다.

이런 에러 처리 기술은 **예외 감싸기**라고 부른다.  
예외 감싸기는 다음과 같은 순서로 진행된다.

1. 데이터 읽기와 같은 포괄적인 에러를 대변하는 새로운 클래스 `ReadError`를 만든다.
2. 함수 `readUser` 발생한 `ValidationError`, `SyntaxError` 등의 에러는 `readUser` 내부에서 잡고 이때 `ReadError`를 생성한다.
3. `ReadError` 객체의 `cause` 프로퍼티엔 실제 에러에 대한 참조가 저장된다.

이렇게 예외 감싸기 기술을 써 스키마를 변경하면 `readUser`를 호출하는 코드에서는 `ReadError`만 확인하면 된다.  
데이터를 읽을 때 발생하는 에러 종류 전체를 확인하지 않아도 된다.  
추가 정보가 필요한 경우엔 `cause` 프로퍼티를 확인하면 된다.

이제 실제로 `ReadError`를 정의하고 이를 사용해보자.

```js
class ReadError extends Error {
  constructor(message, cause) {
    super(message);
    this.cause = cause;
    this.name = 'ReadError';
  }
}

class ValidationError extends Error {}
class PropertyRequiredError extends ValidationError {}

function validateUser(user) {
  if (!user.age) {
    throw new PropertyRequiredError("age");
  }

  if (!user.name) {
    throw new PropertyRequiredError("name");
  }
}

function readUser(json) {
  let user;
  try {
    user = JSON.parse(json);
  } catch (err) {
    if (err instanceof SyntaxError) {
      throw new ReadError("Syntax Error", err);
    } else {
      throw err;
    }
  }

  try {
    validateUser(user);
  } catch (err) {
    if (err instanceof ValidationError) {
      throw new ReadError("Validation Error", err);
    } else {
      throw err;
    }
  }

  try {
    readUser('{잘못된 형식의 json}');
  } catch (e) {
    alert(e); 
    alert("Original error: " + e.cause);
  }
}
```

이제 `readUser`는 위에서 설명한 것처럼 동작한다.  
`SyntaxError`나 `ValidationError`가 발생한 경우 해당 에러 자체를 다시 던지지 않고 `ReadError`를 던지게 된다.

이렇게 되면 `readUser`를 호출하는 바깥 코드에서는 `instanceof ReadError` 딱 하나만 확인하면 된다.  
에러 처리 분기문을 여러 개 만들 필요가 없어진다.

**예외 감싸기**란 이름은 종류별 에러를 좀 더 추상적인 에러인 `ReadError`에 하나로 모아 처리하기 때문에 붙여졌다.  
이런 기법은 객체 지향 프로그래밍에서 널리 쓰이는 패턴이다.
